# 22장. 실패 처리하기

>~~테스트 메서드 호출하기~~
>
>~~먼저 setUp 호출하기~~
>
>~~나중에 tearDown 호출하기~~
>
>테스트 메서드가 실패하더라도 tearDown 호출하기
>
>테스트 여러 개 실행하기
>
>~~수집한 결과를 출력하기~~
>
>~~WasRun에 로그 문자열 남기기~~
>
>**(new) 실패한 테스트 보고하기**



우리는 실패한 테스트를 발견하면 좀 더 세밀한 단위의 테스트를 작성해서 올바른 결과를 출력하는 걸 확인하겠다.

#### 📌 TestCaseTest

```python
def testFailedResultFormatting(self):
  result = TestResult()
  result.testStarted()
  result.testFailed()
  assert("1 run, 1 failed" == result.summary())
```

- (❓) testStarted()와 testFailed()는 각각 테스트가 시작될때와 실패할 때 보낼 메시지다. 
  - 구현은 실패 횟수를 세는 것인데
- 요약 문자열이 제대로 출력된다면 문제는 어떻게 이 메시지들을 보낼 것인가 하는것으로 좁혀진다.
- 일단 메시지를 보내기만 하면 전체가 제대로 동작할 거라는 걸 예상할 수 있다.



#### 📌 TestResult

```python
def __init__(self):
  self.runCount = 0
  self.failureCount = 0
def testFailed(self):
  self.failureCount = self.failureCount + 1
```

#### 📌 TestResult

```python
def summary(self):
  return "%d run, %d failed" % (self.runCount, self.failureCount)
```



자 이제 testFailed()만 제대로 호출하면 예상되는 답을 얻을 수 있다.

언제 호출할까?

- 테스트 메서드에서 던진 예외를 잡았을 때!



#### 📌 TestCase

```python
def run(self):
  result = TestResult()
  result.testStarted()
  self.setUp()
  try:
    method = getattr(self, self.name)
    method()
  except:
    result.testFailed()
 	self.tearDown()
  return result
```

- setUp()에서 문제가 발생하면 우리는 처리할 수 없다.
  - 우리가 바라는게 아니므로 할일 목록에 넣는다.



#### 이번장에서 우리는

- 작은 스케일의 테스트가 통과하게 만들었다.
- 큰 스케일의 테스트를 다시 도입했다.
- 작은 스케일의 테스트에서 보았던 메커니즘을 이용해서 큰 스케일의 테스트를 빠르게 통과시켰다.
- 중요한 문제를 발견했는데 이를 바로 처리하기 보다는 할일 목록에 적어두었다.